<?xml version="1.0" ?>
<robot name="stretch_description" version="1.0">
  <link name="link_gripper">
    <inertial>
      <origin rpy="0.0 0.0 0.0" xyz="-0.017022913273 0.0131410320934 -0.0371614759485"/>
      <mass value="0.101902711393"/>
      <inertia ixx="2.79241618018e-05" ixy="-1.1081924745e-05" ixz="-1.50343284037e-05" iyy="3.67945130513e-05" iyz="-4.33280448536e-06" izz="4.14524691955e-05"/>
    </inertial>
    <visual>
      <origin rpy="0.0 0.0 0.0" xyz="0.0 0.0 0.0"/>
      <geometry>
        <mesh filename="package://stretch_description/meshes/link_gripper.STL"/>
      </geometry>
      <material name="">
        <color rgba="0.792156862745 0.819607843137 0.933333333333 1.0"/>
      </material>
    </visual>
    <collision>
      <origin rpy="0.0 0.0 0.0" xyz="0.0 0.0 0.0"/>
      <geometry>
        <mesh filename="package://stretch_description/meshes/link_gripper.STL"/>
      </geometry>
    </collision>
  </link>
  <joint name="joint_gripper" type="fixed">
    <origin rpy="3.14159 0.0 -1.5708" xyz="0.0 0.0 0.0"/>
    <axis xyz="0.0 0.0 0.0"/>
    <parent link="link_wrist_yaw"/>
    <child link="link_gripper"/>
  </joint>
  <link name="link_gripper_finger_left">
    <inertial>
      <origin rpy="0.0 0.0 0.0" xyz="0.094504748351 0.0124301080924 -4.4408920985e-16"/>
      <mass value="0.0476207785199"/>
      <inertia ixx="0.0" ixy="0.0" ixz="0.0" iyy="0.0" iyz="0.0" izz="0.0"/>
    </inertial>
    <visual>
      <origin rpy="0.0 0.0 0.0" xyz="0.0 0.0 0.0"/>
      <geometry>
        <mesh filename="package://stretch_description/meshes/link_gripper_finger_left.STL" scale="0.9 1.0 1.0"/>
      </geometry>
      <material name="">
        <color rgba="0.792156862745 0.819607843137 0.933333333333 1.0"/>
      </material>
    </visual>
    <collision>
      <origin rpy="0.0 0.0 0.0" xyz="0.0 0.0 0.0"/>
      <geometry>
        <mesh filename="package://stretch_description/meshes/link_gripper_finger_left.STL" scale="0.9 1.0 1.0"/>
      </geometry>
    </collision>
  </link>
  <joint name="joint_gripper_finger_left" type="revolute">
    <origin rpy="2.1762e-15 0.5236 3.1416" xyz="-0.047231 -0.010151 -0.04679"/>
    <axis xyz="0.0 0.0 1.0"/>
    <parent link="link_gripper"/>
    <child link="link_gripper_finger_left"/>
    <limit effort="100.0" lower="-0.6" upper="0.6" velocity="1.0"/>
  </joint>
  <link name="link_gripper_fingertip_left">
    <inertial>
      <origin rpy="0.0 0.0 0.0" xyz="-3.16381381649e-08 -2.91408530639e-09 0.00812579670382"/>
      <mass value="0.00382159917456"/>
      <inertia ixx="0.0" ixy="0.0" ixz="0.0" iyy="0.0" iyz="0.0" izz="0.0"/>
    </inertial>
    <visual>
      <origin rpy="0.0 0.0 0.0" xyz="0.0 0.0 0.0"/>
      <geometry>
        <mesh filename="package://stretch_description/meshes/link_gripper_fingertip_left.STL"/>
      </geometry>
      <material name="">
        <color rgba="0.250980392157 0.250980392157 0.250980392157 1.0"/>
      </material>
    </visual>
    <collision>
      <origin rpy="0.0 0.0 0.0" xyz="0.0 0.0 0.0"/>
      <geometry>
        <mesh filename="package://stretch_description/meshes/link_gripper_fingertip_left.STL"/>
      </geometry>
    </collision>
  </link>
  <joint name="joint_gripper_fingertip_left" type="fixed">
    <origin rpy="-1.5708 -4.774e-15 -2.5545" xyz="0.171099 0.014912 0.0"/>
    <axis xyz="0.0 0.0 0.0"/>
    <parent link="link_gripper_finger_left"/>
    <child link="link_gripper_fingertip_left"/>
  </joint>
  <link name="link_gripper_finger_right">
    <inertial>
      <origin rpy="0.0 0.0 0.0" xyz="-0.094504748351 -0.0124301080924 0.0"/>
      <mass value="0.0476207785199"/>
      <inertia ixx="0.0" ixy="0.0" ixz="0.0" iyy="0.0" iyz="0.0" izz="0.0"/>
    </inertial>
    <visual>
      <origin rpy="0.0 0.0 0.0" xyz="0.0 0.0 0.0"/>
      <geometry>
        <mesh filename="package://stretch_description/meshes/link_gripper_finger_right.STL" scale="0.9 1.0 1.0"/>
      </geometry>
      <material name="">
        <color rgba="0.792156862745 0.819607843137 0.933333333333 1.0"/>
      </material>
    </visual>
    <collision>
      <origin rpy="0.0 0.0 0.0" xyz="0.0 0.0 0.0"/>
      <geometry>
        <mesh filename="package://stretch_description/meshes/link_gripper_finger_right.STL" scale="0.9 1.0 1.0"/>
      </geometry>
    </collision>
  </link>
  <joint name="joint_gripper_finger_right" type="revolute">
    <origin rpy="3.1416 -0.5236 1.2943e-15" xyz="-0.047231 0.010049 -0.04679"/>
    <axis xyz="0.0 0.0 1.0"/>
    <parent link="link_gripper"/>
    <child link="link_gripper_finger_right"/>
    <limit effort="100.0" lower="-0.6" upper="0.6" velocity="1.0"/>
  </joint>
  <link name="link_gripper_fingertip_right">
    <inertial>
      <origin rpy="0.0 0.0 0.0" xyz="2.59386303963e-08 6.70949018566e-09 0.0081257951613"/>
      <mass value="0.0038216003732"/>
      <inertia ixx="0.0" ixy="0.0" ixz="0.0" iyy="0.0" iyz="0.0" izz="0.0"/>
    </inertial>
    <visual>
      <origin rpy="0.0 0.0 0.0" xyz="0.0 0.0 0.0"/>
      <geometry>
        <mesh filename="package://stretch_description/meshes/link_gripper_fingertip_right.STL"/>
      </geometry>
      <material name="">
        <color rgba="0.250980392157 0.250980392157 0.250980392157 1.0"/>
      </material>
    </visual>
    <collision>
      <origin rpy="0.0 0.0 0.0" xyz="0.0 0.0 0.0"/>
      <geometry>
        <mesh filename="package://stretch_description/meshes/link_gripper_fingertip_right.STL"/>
      </geometry>
    </collision>
  </link>
  <joint name="joint_gripper_fingertip_right" type="fixed">
    <origin rpy="-1.5708 -2.0539e-15 0.58705" xyz="-0.171099 -0.014912 0.0"/>
    <axis xyz="0.0 0.0 0.0"/>
    <parent link="link_gripper_finger_right"/>
    <child link="link_gripper_fingertip_right"/>
  </joint>
  <link name="link_grasp_center"/>
  <joint name="joint_grasp_center" type="fixed">
    <origin rpy="0.0 0.0 3.141579" xyz="-0.205478 0.0 -0.138154"/>
    <parent link="link_gripper"/>
    <child link="link_grasp_center"/>
  </joint>
  <link name="base_link">
    <inertial>
      <origin rpy="0.0 0.0 0.0" xyz="-0.109461304328 -0.000741018909048 0.091491526943"/>
      <mass value="1.07237826598"/>
      <inertia ixx="0.0031058090771" ixy="1.51828481911e-06" ixz="0.000416904667324" iyy="0.00433798719992" iyz="1.33487716258e-05" izz="0.00372047274674"/>
    </inertial>
    <visual>
      <origin rpy="0.0 0.0 0.0" xyz="0.0 0.0 0.0"/>
      <geometry>
        <mesh filename="package://stretch_description/meshes/base_link.STL"/>
      </geometry>
      <material name="">
        <color rgba="0.792156862745 0.819607843137 0.933333333333 1.0"/>
      </material>
    </visual>
    <collision>
      <origin rpy="0.0 0.0 0.0" xyz="0.0 0.0 0.0"/>
      <geometry>
        <mesh filename="package://stretch_description/meshes/base_link.STL"/>
      </geometry>
    </collision>
  </link>
  <link name="link_right_wheel">
    <inertial>
      <origin rpy="0.0 0.0 0.0" xyz="1.25554620867e-07 3.54748938447e-07 0.0239581106165"/>
      <mass value="0.00356714564938"/>
      <inertia ixx="0.0" ixy="0.0" ixz="0.0" iyy="0.0" iyz="0.0" izz="0.0"/>
    </inertial>
    <visual>
      <origin rpy="0.0 0.0 0.0" xyz="0.0 0.0 0.0"/>
      <geometry>
        <mesh filename="package://stretch_description/meshes/link_right_wheel.STL"/>
      </geometry>
      <material name="">
        <color rgba="0.792156862745 0.819607843137 0.933333333333 1.0"/>
      </material>
    </visual>
    <collision>
      <origin rpy="0.0 0.0 0.0" xyz="0.0 0.0 0.0"/>
      <geometry>
        <mesh filename="package://stretch_description/meshes/link_right_wheel.STL"/>
      </geometry>
    </collision>
  </link>
  <joint name="joint_right_wheel" type="continuous">
    <origin rpy="-1.57079632679 -1.11022302463e-16 7.2858385991e-17" xyz="-0.003 -0.15765 0.0508"/>
    <axis xyz="0.0 0.0 1.0"/>
    <parent link="base_link"/>
    <child link="link_right_wheel"/>
  </joint>
  <link name="link_left_wheel">
    <inertial>
      <origin rpy="0.0 0.0 0.0" xyz="1.25554620922e-07 -3.54748938503e-07 -0.0239581106165"/>
      <mass value="0.00356714564938"/>
      <inertia ixx="0.0" ixy="0.0" ixz="0.0" iyy="0.0" iyz="0.0" izz="0.0"/>
    </inertial>
    <visual>
      <origin rpy="0.0 0.0 0.0" xyz="0.0 0.0 0.0"/>
      <geometry>
        <mesh filename="package://stretch_description/meshes/link_left_wheel.STL"/>
      </geometry>
      <material name="">
        <color rgba="0.792156862745 0.819607843137 0.933333333333 1.0"/>
      </material>
    </visual>
    <collision>
      <origin rpy="0.0 0.0 0.0" xyz="0.0 0.0 0.0"/>
      <geometry>
        <mesh filename="package://stretch_description/meshes/link_left_wheel.STL"/>
      </geometry>
    </collision>
  </link>
  <joint name="joint_left_wheel" type="continuous">
    <origin rpy="-1.57079632679 3.16227047921e-31 7.88745438254e-16" xyz="-0.00300000000002 0.15765 0.0508"/>
    <axis xyz="0.0 0.0 1.0"/>
    <parent link="base_link"/>
    <child link="link_left_wheel"/>
  </joint>
  <link name="link_mast">
    <inertial>
      <origin rpy="0.0 0.0 0.0" xyz="0.00755818572976 0.773971284177 0.0064731308662"/>
      <mass value="0.749143203376"/>
      <inertia ixx="0.0709854511955" ixy="-0.00433428742758" ixz="-0.000186110788698" iyy="0.000437922053343" iyz="-0.00288788257713" izz="0.0711048085017"/>
    </inertial>
    <visual>
      <origin rpy="0.0 0.0 0.0" xyz="0.0 0.0 0.0"/>
      <geometry>
        <mesh filename="package://stretch_description/meshes/link_mast.STL"/>
      </geometry>
      <material name="">
        <color rgba="0.792156862745 0.819607843137 0.933333333333 1.0"/>
      </material>
    </visual>
    <collision>
      <origin rpy="0.0 0.0 0.0" xyz="0.0 0.0 0.0"/>
      <geometry>
        <mesh filename="package://stretch_description/meshes/link_mast.STL"/>
      </geometry>
    </collision>
  </link>
  <joint name="joint_mast" type="fixed">
    <origin rpy="1.5799781284266465 0.028175469553935795 0.018121094047751266" xyz="-0.07728081280016906 0.1397241022999293 0.031058526588298833"/>
    <axis xyz="0.0 0.0 0.0"/>
    <parent link="base_link"/>
    <child link="link_mast"/>
  </joint>
  <link name="link_lift">
    <inertial>
      <origin rpy="0.0 0.0 0.0" xyz="-0.0547636346253 0.0380939689802 0.00933159404448"/>
      <mass value="0.444820831236"/>
      <inertia ixx="0.000567192946271" ixy="-0.000246075347895" ixz="-0.000128108442261" iyy="0.00127108364479" iyz="7.6191685507e-06" izz="0.00137296635099"/>
    </inertial>
    <visual>
      <origin rpy="0.0 0.0 0.0" xyz="0.0 0.0 0.0"/>
      <geometry>
        <mesh filename="package://stretch_description/meshes/link_lift.STL"/>
      </geometry>
      <material name="">
        <color rgba="0.792156862745 0.819607843137 0.933333333333 1.0"/>
      </material>
    </visual>
    <collision>
      <origin rpy="0.0 0.0 0.0" xyz="0.0 0.0 0.0"/>
      <geometry>
        <mesh filename="package://stretch_description/meshes/link_lift.STL"/>
      </geometry>
    </collision>
  </link>
  <joint name="joint_lift" type="prismatic">
    <origin rpy="-1.5707963268 1.56154313753 -6.29420043665e-13" xyz="-0.0369217062323 0.1654712 -0.000341653286794"/>
    <axis xyz="0.0 0.0 1.0"/>
    <parent link="link_mast"/>
    <child link="link_lift"/>
    <limit effort="100.0" lower="0.0" upper="1.1" velocity="1.0"/>
  </joint>
  <link name="link_arm_l4">
    <inertial>
      <origin rpy="0.0 0.0 0.0" xyz="-1.61247276464e-06 1.54715589201e-06 -0.095325270604"/>
      <mass value="0.067652545579"/>
      <inertia ixx="0.000122002023067" ixy="7.2959335623e-13" ixz="9.63170353371e-09" iyy="0.000122002023127" iyz="-9.24154949889e-09" izz="1.4604343981e-12"/>
    </inertial>
    <visual>
      <origin rpy="0.0 0.0 0.0" xyz="0.0 0.0 0.0"/>
      <geometry>
        <mesh filename="package://stretch_description/meshes/link_arm_l4.STL"/>
      </geometry>
      <material name="">
        <color rgba="0.792156862745 0.819607843137 0.933333333333 1.0"/>
      </material>
    </visual>
    <collision>
      <origin rpy="0.0 0.0 0.0" xyz="0.0 0.0 0.0"/>
      <geometry>
        <mesh filename="package://stretch_description/meshes/link_arm_l4.STL"/>
      </geometry>
    </collision>
  </link>
  <joint name="joint_arm_l4" type="fixed">
    <origin rpy="1.581934003432117 0.004825000464821816 -1.5836211915732903" xyz="-0.2573311213650146 0.0006318967931893909 -0.0033320082911183265"/>
    <axis xyz="0.0 0.0 0.0"/>
    <parent link="link_lift"/>
    <child link="link_arm_l4"/>
  </joint>
  <link name="link_arm_l3">
    <inertial>
      <origin rpy="0.0 0.0 0.0" xyz="-3.34873468621e-07 4.74113363069e-07 -0.0974069598289"/>
      <mass value="0.0626921047058"/>
      <inertia ixx="0.000115246639451" ixy="4.42139679831e-14" ixz="1.8971127991e-09" iyy="0.00011524663942" iyz="-2.68592949588e-09" izz="9.38270676408e-14"/>
    </inertial>
    <visual>
      <origin rpy="0.0 0.0 0.0" xyz="0.0 0.0 0.0"/>
      <geometry>
        <mesh filename="package://stretch_description/meshes/link_arm_l3.STL"/>
      </geometry>
      <material name="">
        <color rgba="0.792156862745 0.819607843137 0.933333333333 1.0"/>
      </material>
    </visual>
    <collision>
      <origin rpy="0.0 0.0 0.0" xyz="0.0 0.0 0.0"/>
      <geometry>
        <mesh filename="package://stretch_description/meshes/link_arm_l3.STL"/>
      </geometry>
    </collision>
  </link>
  <joint name="joint_arm_l3" type="prismatic">
    <origin rpy="3.5742e-16 3.2123e-16 -2.4565e-16" xyz="0.0 0.0 0.013"/>
    <axis xyz="0.0 0.0 1.0"/>
    <parent link="link_arm_l4"/>
    <child link="link_arm_l3"/>
    <limit effort="100.0" lower="0.0" upper="0.13" velocity="1.0"/>
  </joint>
  <link name="link_arm_l2">
    <inertial>
      <origin rpy="0.0 0.0 0.0" xyz="-3.31043560509e-07 3.13422303999e-07 -0.0972558835419"/>
      <mass value="0.0569074368576"/>
      <inertia ixx="0.000105206697152" ixy="2.59896259031e-14" ixz="1.69941454518e-09" iyy="0.000105206697155" iyz="-1.60895568924e-09" izz="5.20570301686e-14"/>
    </inertial>
    <visual>
      <origin rpy="0.0 0.0 0.0" xyz="0.0 0.0 0.0"/>
      <geometry>
        <mesh filename="package://stretch_description/meshes/link_arm_l2.STL"/>
      </geometry>
      <material name="">
        <color rgba="0.792156862745 0.819607843137 0.933333333333 1.0"/>
      </material>
    </visual>
    <collision>
      <origin rpy="0.0 0.0 0.0" xyz="0.0 0.0 0.0"/>
      <geometry>
        <mesh filename="package://stretch_description/meshes/link_arm_l2.STL"/>
      </geometry>
    </collision>
  </link>
  <joint name="joint_arm_l2" type="prismatic">
    <origin rpy="2.91385731014e-16 4.44300759505e-17 3.25691080516e-16" xyz="0.0 0.0 0.013"/>
    <axis xyz="0.0 0.0 1.0"/>
    <parent link="link_arm_l3"/>
    <child link="link_arm_l2"/>
    <limit effort="100.0" lower="0.0" upper="0.13" velocity="1.0"/>
  </joint>
  <link name="link_arm_l1">
    <inertial>
      <origin rpy="0.0 0.0 0.0" xyz="-3.36876635421e-07 3.05876091067e-07 -0.0969117032233"/>
      <mass value="0.0511763619538"/>
      <inertia ixx="9.58490021275e-05" ixy="2.27446667584e-14" ixz="1.54951672296e-09" iyy="9.58490021319e-05" iyz="-1.40692486873e-09" izz="4.57014633924e-14"/>
    </inertial>
    <visual>
      <origin rpy="0.0 0.0 0.0" xyz="0.0 0.0 0.0"/>
      <geometry>
        <mesh filename="package://stretch_description/meshes/link_arm_l1.STL"/>
      </geometry>
      <material name="">
        <color rgba="0.792156862745 0.819607843137 0.933333333333 1.0"/>
      </material>
    </visual>
    <collision>
      <origin rpy="0.0 0.0 0.0" xyz="0.0 0.0 0.0"/>
      <geometry>
        <mesh filename="package://stretch_description/meshes/link_arm_l1.STL"/>
      </geometry>
    </collision>
  </link>
  <joint name="joint_arm_l1" type="prismatic">
    <origin rpy="7.41596560408e-17 1.33876788297e-16 -2.44545873596e-16" xyz="0.0 0.0 0.013"/>
    <axis xyz="0.0 0.0 1.0"/>
    <parent link="link_arm_l2"/>
    <child link="link_arm_l1"/>
    <limit effort="100.0" lower="0.0" upper="0.13" velocity="1.0"/>
  </joint>
  <link name="link_arm_l0">
    <inertial>
      <origin rpy="0.0 0.0 0.0" xyz="0.0230715049668 -0.00195115833663 -0.036064634716"/>
      <mass value="0.101241250325"/>
      <inertia ixx="0.00022715699901" ixy="8.90680620109e-06" ixz="-7.91132210986e-05" iyy="0.000300732790537" iyz="7.21771824541e-06" izz="9.35784422622e-05"/>
    </inertial>
    <visual>
      <origin rpy="0.0 0.0 0.0" xyz="0.0 0.0 0.0"/>
      <geometry>
        <mesh filename="package://stretch_description/meshes/link_arm_l0.STL"/>
      </geometry>
      <material name="">
        <color rgba="0.792156862745 0.819607843137 0.933333333333 1.0"/>
      </material>
    </visual>
    <collision>
      <origin rpy="0.0 0.0 0.0" xyz="0.0 0.0 0.0"/>
      <geometry>
        <mesh filename="package://stretch_description/meshes/link_arm_l0.STL"/>
      </geometry>
    </collision>
  </link>
  <joint name="joint_arm_l0" type="prismatic">
    <origin rpy="-3.05317390622e-16 -4.23236224077e-16 -2.68425135229e-17" xyz="0.0 0.0 -0.01375"/>
    <axis xyz="0.0 0.0 1.0"/>
    <parent link="link_arm_l1"/>
    <child link="link_arm_l0"/>
    <limit effort="100.0" lower="0.0" upper="0.13" velocity="1.0"/>
  </joint>
  <link name="link_wrist_yaw">
    <inertial>
      <origin rpy="0.0 0.0 0.0" xyz="-8.02795716751e-06 1.93811447768e-05 0.0189467005959"/>
      <mass value="0.0405398981326"/>
      <inertia ixx="2.20062857967e-09" ixy="1.15494401227e-13" ixz="1.02598056874e-11" iyy="2.20039759185e-09" iyz="-2.47692875363e-11" izz="3.26666802417e-13"/>
    </inertial>
    <visual>
      <origin rpy="0.0 0.0 0.0" xyz="0.0 0.0 0.0"/>
      <geometry>
        <mesh filename="package://stretch_description/meshes/link_wrist_yaw.STL"/>
      </geometry>
      <material name="">
        <color rgba="0.792156862745 0.819607843137 0.933333333333 1.0"/>
      </material>
    </visual>
    <collision>
      <origin rpy="0.0 0.0 0.0" xyz="0.0 0.0 0.0"/>
      <geometry>
        <mesh filename="package://stretch_description/meshes/link_wrist_yaw.STL"/>
      </geometry>
    </collision>
  </link>
  <joint name="joint_wrist_yaw" type="revolute">
    <origin rpy="1.5708 4.2595e-14 2.6415e-15" xyz="0.083 -0.03075 0.0"/>
    <axis xyz="0.0 0.0 -1.0"/>
    <parent link="link_arm_l0"/>
    <child link="link_wrist_yaw"/>
    <limit effort="100.0" lower="-1.75" upper="4.0" velocity="1.0"/>
  </joint>
  <link name="link_head">
    <inertial>
      <origin rpy="0.0 0.0 0.0" xyz="0.0372933550589 0.0455094329856 0.0281136801213"/>
      <mass value="0.129454717596"/>
      <inertia ixx="2.93405962311e-05" ixy="-7.89638931854e-07" ixz="-4.74678128516e-06" iyy="2.68283736177e-05" iyz="1.80251508622e-06" izz="1.46172914237e-05"/>
    </inertial>
    <visual>
      <origin rpy="0.0 0.0 0.0" xyz="0.0 0.0 0.0"/>
      <geometry>
        <mesh filename="package://stretch_description/meshes/link_head.STL"/>
      </geometry>
      <material name="">
        <color rgba="0.792156862745 0.819607843137 0.933333333333 1.0"/>
      </material>
    </visual>
    <collision>
      <origin rpy="0.0 0.0 0.0" xyz="0.0 0.0 0.0"/>
      <geometry>
        <mesh filename="package://stretch_description/meshes/link_head.STL"/>
      </geometry>
    </collision>
  </link>
  <joint name="joint_head" type="fixed">
    <origin rpy="1.5708 -1.5615 3.1416" xyz="0.0 1.33 0.0"/>
    <axis xyz="0.0 0.0 0.0"/>
    <parent link="link_mast"/>
    <child link="link_head"/>
  </joint>
  <link name="link_head_pan">
    <inertial>
      <origin rpy="0.0 0.0 0.0" xyz="-0.00116200255311 0.0130365621706 0.00137629842299"/>
      <mass value="0.0358583411826"/>
      <inertia ixx="2.7584793756e-05" ixy="5.25762707914e-07" ixz="-9.28796751053e-07" iyy="2.08815921107e-05" iyz="1.17265055332e-05" izz="6.78612505436e-06"/>
    </inertial>
    <visual>
      <origin rpy="0.0 0.0 0.0" xyz="0.0 0.0 0.0"/>
      <geometry>
        <mesh filename="package://stretch_description/meshes/link_head_pan.STL"/>
      </geometry>
      <material name="">
        <color rgba="0.792156862745 0.819607843137 0.933333333333 1.0"/>
      </material>
    </visual>
    <collision>
      <origin rpy="0.0 0.0 0.0" xyz="0.0 0.0 0.0"/>
      <geometry>
        <mesh filename="package://stretch_description/meshes/link_head_pan.STL"/>
      </geometry>
    </collision>
  </link>
  <joint name="joint_head_pan" type="revolute">
    <origin rpy="0.011693403293892526 0.004580056232997176 1.625904036176185" xyz="0.14064332466991114 0.06930314296413893 -0.009926090799158993"/>
    <axis xyz="0.0 0.0 1.0"/>
    <parent link="link_head"/>
    <child link="link_head_pan"/>
    <limit effort="100.0" lower="-3.9" upper="1.5" velocity="1.0"/>
  </joint>
  <link name="link_head_tilt">
    <inertial>
      <origin rpy="0.0 0.0 0.0" xyz="0.00920211049012 -0.0279724762416 0.0306580436227"/>
      <mass value="0.0701242408063"/>
      <inertia ixx="1.73265934767e-05" ixy="2.38363792824e-07" ixz="7.96430204321e-08" iyy="4.11044416077e-05" iyz="-9.41955638216e-07" izz="2.38851808141e-05"/>
    </inertial>
    <visual>
      <origin rpy="0.0 0.0 0.0" xyz="0.0 0.0 0.0"/>
      <geometry>
        <mesh filename="package://stretch_description/meshes/link_head_tilt.STL"/>
      </geometry>
      <material name="">
        <color rgba="0.792156862745 0.819607843137 0.933333333333 1.0"/>
      </material>
    </visual>
    <collision>
      <origin rpy="0.0 0.0 0.0" xyz="0.0 0.0 0.0"/>
      <geometry>
        <mesh filename="package://stretch_description/meshes/link_head_tilt.STL"/>
      </geometry>
    </collision>
  </link>
  <joint name="joint_head_tilt" type="revolute">
    <origin rpy="1.5476973889159176 -0.05512264295639557 0.050791957909797604" xyz="-0.0017979013411328964 0.02146557221426584 -0.055378939813129836"/>
    <axis xyz="0.0 0.0 1.0"/>
    <parent link="link_head_pan"/>
    <child link="link_head_tilt"/>
    <limit effort="100.0" lower="-1.53" upper="0.79" velocity="1.0"/>
  </joint>
  <link name="link_aruco_right_base">
    <inertial>
      <origin rpy="0.0 0.0 0.0" xyz="0.0 0.0 -5.00000000014e-07"/>
      <mass value="3.5999999999e-06"/>
      <inertia ixx="0.0" ixy="0.0" ixz="0.0" iyy="0.0" iyz="0.0" izz="0.0"/>
    </inertial>
    <visual>
      <origin rpy="0.0 0.0 0.0" xyz="0.0 0.0 0.0"/>
      <geometry>
        <mesh filename="package://stretch_description/meshes/link_aruco_right_base.STL"/>
      </geometry>
      <material name="">
        <color rgba="0.792156862745 0.819607843137 0.933333333333 1.0"/>
      </material>
    </visual>
    <collision>
      <origin rpy="0.0 0.0 0.0" xyz="0.0 0.0 0.0"/>
      <geometry>
        <mesh filename="package://stretch_description/meshes/link_aruco_right_base.STL"/>
      </geometry>
    </collision>
  </link>
  <joint name="joint_aruco_right_base" type="fixed">
    <origin rpy="0.0 0.0 -1.57079632679" xyz="-0.005 -0.1304972 0.1597482"/>
    <axis xyz="0.0 0.0 0.0"/>
    <parent link="base_link"/>
    <child link="link_aruco_right_base"/>
  </joint>
  <link name="link_aruco_left_base">
    <inertial>
      <origin rpy="0.0 0.0 0.0" xyz="0.0 0.0 -5.00000000014e-07"/>
      <mass value="3.5999999999e-06"/>
      <inertia ixx="0.0" ixy="0.0" ixz="0.0" iyy="0.0" iyz="0.0" izz="0.0"/>
    </inertial>
    <visual>
      <origin rpy="0.0 0.0 0.0" xyz="0.0 0.0 0.0"/>
      <geometry>
        <mesh filename="package://stretch_description/meshes/link_aruco_left_base.STL"/>
      </geometry>
      <material name="">
        <color rgba="0.792156862745 0.819607843137 0.933333333333 1.0"/>
      </material>
    </visual>
    <collision>
      <origin rpy="0.0 0.0 0.0" xyz="0.0 0.0 0.0"/>
      <geometry>
        <mesh filename="package://stretch_description/meshes/link_aruco_left_base.STL"/>
      </geometry>
    </collision>
  </link>
  <joint name="joint_aruco_left_base" type="fixed">
    <origin rpy="0.0 0.0 -1.57079632679" xyz="-0.005 0.1304972 0.1597482"/>
    <axis xyz="0.0 0.0 0.0"/>
    <parent link="base_link"/>
    <child link="link_aruco_left_base"/>
  </joint>
  <link name="link_aruco_shoulder">
    <inertial>
      <origin rpy="0.0 0.0 0.0" xyz="-2.77555756156e-17 2.56739074445e-16 -0.000125"/>
      <mass value="0.000399141592654"/>
      <inertia ixx="0.0" ixy="0.0" ixz="0.0" iyy="0.0" iyz="0.0" izz="0.0"/>
    </inertial>
    <visual>
      <origin rpy="0.0 0.0 0.0" xyz="0.0 0.0 0.0"/>
      <geometry>
        <mesh filename="package://stretch_description/meshes/link_aruco_shoulder.STL"/>
      </geometry>
      <material name="">
        <color rgba="0.792156862745 0.819607843137 0.933333333333 1.0"/>
      </material>
    </visual>
    <collision>
      <origin rpy="0.0 0.0 0.0" xyz="0.0 0.0 0.0"/>
      <geometry>
        <mesh filename="package://stretch_description/meshes/link_aruco_shoulder.STL"/>
      </geometry>
    </collision>
  </link>
  <joint name="joint_aruco_shoulder" type="fixed">
    <origin rpy="-1.53998860118e-29 3.55962409571e-15 0.0" xyz="-0.0133768876375 0.0558540528812 0.0861368272418"/>
    <axis xyz="0.0 0.0 0.0"/>
    <parent link="link_lift"/>
    <child link="link_aruco_shoulder"/>
  </joint>
  <link name="link_aruco_top_wrist">
    <inertial>
      <origin rpy="0.0 0.0 0.0" xyz="1.11022302463e-16 3.05311331772e-16 -0.000124999999998"/>
      <mass value="0.000225"/>
      <inertia ixx="0.0" ixy="0.0" ixz="0.0" iyy="0.0" iyz="0.0" izz="0.0"/>
    </inertial>
    <visual>
      <origin rpy="0.0 0.0 0.0" xyz="0.0 0.0 0.0"/>
      <geometry>
        <mesh filename="package://stretch_description/meshes/link_aruco_top_wrist.STL"/>
      </geometry>
      <material name="">
        <color rgba="0.792156862745 0.819607843137 0.933333333333 1.0"/>
      </material>
    </visual>
    <collision>
      <origin rpy="0.0 0.0 0.0" xyz="0.0 0.0 0.0"/>
      <geometry>
        <mesh filename="package://stretch_description/meshes/link_aruco_top_wrist.STL"/>
      </geometry>
    </collision>
  </link>
  <joint name="joint_aruco_top_wrist" type="fixed">
    <origin rpy="1.57079632679 -8.03728587323e-15 3.14159265359" xyz="0.04725 0.029285 0.0"/>
    <axis xyz="0.0 0.0 0.0"/>
    <parent link="link_arm_l0"/>
    <child link="link_aruco_top_wrist"/>
  </joint>
  <link name="link_aruco_inner_wrist">
    <inertial>
      <origin rpy="0.0 0.0 0.0" xyz="8.32667268469e-17 1.7763568394e-15 -0.000125"/>
      <mass value="0.000225"/>
      <inertia ixx="0.0" ixy="0.0" ixz="0.0" iyy="0.0" iyz="0.0" izz="0.0"/>
    </inertial>
    <visual>
      <origin rpy="0.0 0.0 0.0" xyz="0.0 0.0 0.0"/>
      <geometry>
        <mesh filename="package://stretch_description/meshes/link_aruco_inner_wrist.STL"/>
      </geometry>
      <material name="">
        <color rgba="0.792156862745 0.819607843137 0.933333333333 1.0"/>
      </material>
    </visual>
    <collision>
      <origin rpy="0.0 0.0 0.0" xyz="0.0 0.0 0.0"/>
      <geometry>
        <mesh filename="package://stretch_description/meshes/link_aruco_inner_wrist.STL"/>
      </geometry>
    </collision>
  </link>
  <joint name="joint_aruco_inner_wrist" type="fixed">
    <origin rpy="3.14159265359 4.23377442363e-14 3.14159265359" xyz="0.04725 -0.0119 -0.0272499999992"/>
    <axis xyz="0.0 0.0 0.0"/>
    <parent link="link_arm_l0"/>
    <child link="link_aruco_inner_wrist"/>
  </joint>
  <material name="aluminum">
    <color rgba="0.5 0.5 0.5 1.0"/>
  </material>
  <material name="plastic">
    <color rgba="0.1 0.1 0.1 1.0"/>
  </material>
  <joint name="camera_joint" type="fixed">
    <origin rpy="0.015154130136121975 0.03753104662476536 0.010955332078839872" xyz="0.027175820833434026 -0.008204096803894799 0.018527585123845534"/>
    <parent link="link_head_tilt"/>
    <child link="camera_bottom_screw_frame"/>
  </joint>
  <link name="camera_bottom_screw_frame"/>
  <joint name="camera_link_joint" type="fixed">
    <origin rpy="0.0 0.0 0.0" xyz="0.0106 0.0175 0.0125"/>
    <parent link="camera_bottom_screw_frame"/>
    <child link="camera_link"/>
  </joint>
  <link name="camera_link">
    <inertial>
      <origin rpy="0 0 0" xyz="0.0 0.0 0.0"/>
      <mass value="0.564"/>
      <inertia ixx="0.003881243" ixy="0.0" ixz="0.0" iyy="0.00049894" iyz="0.0" izz="0.003879257"/>
    </inertial>
    <visual>
      <origin rpy="1.57079632679 0.0 1.57079632679" xyz="0.0043 -0.0175 0.0"/>
      <geometry>
        <mesh filename="package://realsense2_description/meshes/d435.dae"/>
      </geometry>
    </visual>
    <collision>
      <origin rpy="0.0 0.0 0.0" xyz="0.0 -0.0175 0.0"/>
      <geometry>
        <box size="0.02505 0.09 0.025"/>
      </geometry>
    </collision>
  </link>
  <joint name="camera_depth_joint" type="fixed">
    <origin rpy="0.0 0.0 0.0" xyz="0.0 0.0 0.0"/>
    <parent link="camera_link"/>
    <child link="camera_depth_frame"/>
  </joint>
  <link name="camera_depth_frame"/>
  <joint name="camera_depth_optical_joint" type="fixed">
    <origin rpy="-1.57079632679 0.0 -1.57079632679" xyz="0.0 0.0 0.0"/>
    <parent link="camera_depth_frame"/>
    <child link="camera_depth_optical_frame"/>
  </joint>
  <link name="camera_depth_optical_frame"/>
  <joint name="camera_infra1_joint" type="fixed">
    <origin rpy="0.0 0.0 0.0" xyz="0.0 0.0 0.0"/>
    <parent link="camera_link"/>
    <child link="camera_infra1_frame"/>
  </joint>
  <link name="camera_infra1_frame"/>
  <joint name="camera_infra1_optical_joint" type="fixed">
    <origin rpy="-1.57079632679 0.0 -1.57079632679" xyz="0.0 0.0 0.0"/>
    <parent link="camera_infra1_frame"/>
    <child link="camera_infra1_optical_frame"/>
  </joint>
  <link name="camera_infra1_optical_frame"/>
  <joint name="camera_infra2_joint" type="fixed">
    <origin rpy="0.0 0.0 0.0" xyz="0.0 -0.05 0.0"/>
    <parent link="camera_link"/>
    <child link="camera_infra2_frame"/>
  </joint>
  <link name="camera_infra2_frame"/>
  <joint name="camera_infra2_optical_joint" type="fixed">
    <origin rpy="-1.57079632679 0.0 -1.57079632679" xyz="0.0 0.0 0.0"/>
    <parent link="camera_infra2_frame"/>
    <child link="camera_infra2_optical_frame"/>
  </joint>
  <link name="camera_infra2_optical_frame"/>
  <joint name="camera_color_joint" type="fixed">
    <origin rpy="0.0 0.0 0.0" xyz="0.0 0.015 0.0"/>
    <parent link="camera_link"/>
    <child link="camera_color_frame"/>
  </joint>
  <link name="camera_color_frame"/>
  <joint name="camera_color_optical_joint" type="fixed">
    <origin rpy="-1.57079632679 0.0 -1.57079632679" xyz="0.0 0.0 0.0"/>
    <parent link="camera_color_frame"/>
    <child link="camera_color_optical_frame"/>
  </joint>
  <link name="camera_color_optical_frame"/>
  <link name="laser">
    <inertial>
      <origin rpy="0.0 0.0 0.0" xyz="0.0 0.0 -0.000755956127492"/>
      <mass value="0.0749979022894"/>
      <inertia ixx="0.0" ixy="0.0" ixz="0.0" iyy="0.0" iyz="0.0" izz="0.0"/>
    </inertial>
    <visual>
      <origin rpy="0.0 0.0 0.0" xyz="0.0 0.0 0.0"/>
      <geometry>
        <mesh filename="package://stretch_description/meshes/laser.STL"/>
      </geometry>
      <material name="">
        <color rgba="0.250980392157 0.250980392157 0.250980392157 1.0"/>
      </material>
    </visual>
    <collision>
      <origin rpy="0.0 0.0 0.0" xyz="0.0 0.0 0.0"/>
      <geometry>
        <mesh filename="package://stretch_description/meshes/laser.STL"/>
      </geometry>
    </collision>
  </link>
  <joint name="joint_laser" type="fixed">
    <origin rpy="0.0 0.0 -3.14159265359" xyz="0.000502800000001 0.0 0.1664"/>
    <axis xyz="0.0 0.0 0.0"/>
    <parent link="base_link"/>
    <child link="laser"/>
  </joint>
  <link name="respeaker_base">
    <inertial>
      <origin rpy="0.0 0.0 0.0" xyz="-0.000780828967927 0.00765742173486 -0.00424882983019"/>
      <mass value="0.00969129410417"/>
      <inertia ixx="8.95656300428e-07" ixy="2.6733074581e-08" ixz="-3.84519793581e-08" iyy="4.04210996171e-07" iyz="3.15533542839e-07" izz="7.08282597118e-07"/>
    </inertial>
    <visual>
      <origin rpy="0.0 0.0 0.0" xyz="0.0 0.0 0.0"/>
      <geometry>
        <mesh filename="package://stretch_description/meshes/link_respeaker.STL"/>
      </geometry>
      <material name="">
        <color rgba="0.792156862745 0.819607843137 0.933333333333 1.0"/>
      </material>
    </visual>
    <collision>
      <origin rpy="0.0 0.0 0.0" xyz="0.0 0.0 0.0"/>
      <geometry>
        <mesh filename="package://stretch_description/meshes/link_respeaker.STL"/>
      </geometry>
    </collision>
  </link>
  <joint name="joint_respeaker" type="fixed">
    <origin rpy="1.5707963268 0.0 3.14159265359" xyz="1.09074743138e-05 1.36992 0.00303572796911"/>
    <axis xyz="0.0 0.0 0.0"/>
    <parent link="link_mast"/>
    <child link="respeaker_base"/>
  </joint>
</robot>